Workbook

Sheet Supascreen
A1: Supply and Install Supascreen
G2: Pricing as at | H2: 46054 | L2: Percentage Increase | M2: 0.055
C4: Supascreen Windows
C5: 300 | D5: 450 | E5: 600 | F5: 750 | G5: 900 | H5: 1050 | I5: 1200 | J5: 1350 | K5: 1500 | L5: 1650 | M5: 1800 | N5: 1950 | O5: 2100 | P5: 2250 | Q5: 2400 | R5: 2550
B6: 600 | C6: ='Data Sheet SS'!C7*(1+Supascreen!$M$2) -> 154.40724 | D6: ='Data Sheet SS'!D7*(1+Supascreen!$M$2) -> 188.71996 | E6: ='Data Sheet SS'!E7*(1+Supascreen!$M$2) -> 223.03268 | F6: ='Data Sheet SS'!F7*(1+Supascreen!$M$2) -> 257.3454 | G6: ='Data Sheet SS'!G7*(1+Supascreen!$M$2) -> 291.65812 | H6: ='Data Sheet SS'!H7*(1+Supascreen!$M$2) -> 325.97084 | I6: ='Data Sheet SS'!I7*(1+Supascreen!$M$2) -> 360.28356 | J6: ='Data Sheet SS'!J7*(1+Supascreen!$M$2) -> 411.75264 | ... R6: ='Data Sheet SS'!R7*(1+Supascreen!$M$2) -> 686.2544
B7: 750 | C7: ='Data Sheet SS'!C8*(1+Supascreen!$M$2) -> 171.5636 | D7: ='Data Sheet SS'!D8*(1+Supascreen!$M$2) -> 223.03268 | E7: ='Data Sheet SS'!E8*(1+Supascreen!$M$2) -> 257.3454 | F7: ='Data Sheet SS'!F8*(1+Supascreen!$M$2) -> 308.81448 | G7: ='Data Sheet SS'!G8*(1+Supascreen!$M$2) -> 343.1272 | H7: ='Data Sheet SS'!H8*(1+Supascreen!$M$2) -> 377.43992 | I7: ='Data Sheet SS'!I8*(1+Supascreen!$M$2) -> 428.909 | J7: ='Data Sheet SS'!J8*(1+Supascreen!$M$2) -> 497.53444 | ... R7: ='Data Sheet SS'!R8*(1+Supascreen!$M$2) -> 823.50529
B8: 900 | C8: ='Data Sheet SS'!C9*(1+Supascreen!$M$2) -> 188.71996 | D8: ='Data Sheet SS'!D9*(1+Supascreen!$M$2) -> 257.3454 | E8: ='Data Sheet SS'!E9*(1+Supascreen!$M$2) -> 291.65812 | F8: ='Data Sheet SS'!F9*(1+Supascreen!$M$2) -> 343.1272 | G8: ='Data Sheet SS'!G9*(1+Supascreen!$M$2) -> 394.59628 | H8: ='Data Sheet SS'!H9*(1+Supascreen!$M$2) -> 446.06536 | I8: ='Data Sheet SS'!I9*(1+Supascreen!$M$2) -> 497.53444 | J8: ='Data Sheet SS'!J9*(1+Supascreen!$M$2) -> 566.15988 | ... R8: ='Data Sheet SS'!R9*(1+Supascreen!$M$2) -> 960.75617
B9: 1050 | C9: ='Data Sheet SS'!C10*(1+Supascreen!$M$2) -> 205.87632 | D9: ='Data Sheet SS'!D10*(1+Supascreen!$M$2) -> 274.50176 | E9: ='Data Sheet SS'!E10*(1+Supascreen!$M$2) -> 325.97084 | F9: ='Data Sheet SS'!F10*(1+Supascreen!$M$2) -> 377.43992 | G9: ='Data Sheet SS'!G10*(1+Supascreen!$M$2) -> 446.06536 | H9: ='Data Sheet SS'!H10*(1+Supascreen!$M$2) -> 497.53444 | I9: ='Data Sheet SS'!I10*(1+Supascreen!$M$2) -> 566.15988 | J9: ='Data Sheet SS'!J10*(1+Supascreen!$M$2) -> 634.78532 | ... R9: ='Data Sheet SS'!R10*(1+Supascreen!$M$2) -> 1115.1634
B10: 1200 | C10: ='Data Sheet SS'!C11*(1+Supascreen!$M$2) -> 223.03268 | D10: ='Data Sheet SS'!D11*(1+Supascreen!$M$2) -> 291.65812 | E10: ='Data Sheet SS'!E11*(1+Supascreen!$M$2) -> 360.28356 | F10: ='Data Sheet SS'!F11*(1+Supascreen!$M$2) -> 428.909 | G10: ='Data Sheet SS'!G11*(1+Supascreen!$M$2) -> 497.53444 | H10: ='Data Sheet SS'!H11*(1+Supascreen!$M$2) -> 566.15988 | I10: ='Data Sheet SS'!I11*(1+Supascreen!$M$2) -> 634.78532 | J10: ='Data Sheet SS'!J11*(1+Supascreen!$M$2) -> 703.41076 | ... R10: ='Data Sheet SS'!R11*(1+Supascreen!$M$2) -> 1252.4143
B11: 1350 | C11: ='Data Sheet SS'!C12*(1+Supascreen!$M$2) -> 240.18904 | D11: ='Data Sheet SS'!D12*(1+Supascreen!$M$2) -> 325.97084 | E11: ='Data Sheet SS'!E12*(1+Supascreen!$M$2) -> 394.59628 | F11: ='Data Sheet SS'!F12*(1+Supascreen!$M$2) -> 463.22172 | G11: ='Data Sheet SS'!G12*(1+Supascreen!$M$2) -> 549.00352 | H11: ='Data Sheet SS'!H12*(1+Supascreen!$M$2) -> 617.62896 | I11: ='Data Sheet SS'!I12*(1+Supascreen!$M$2) -> 703.41076 | J11: ='Data Sheet SS'!J12*(1+Supascreen!$M$2) -> 789.19257 | ... R11: ='Data Sheet SS'!R12*(1+Supascreen!$M$2) -> 1389.6652
B12: 1500 | C12: ='Data Sheet SS'!C13*(1+Supascreen!$M$2) -> 257.3454 | D12: ='Data Sheet SS'!D13*(1+Supascreen!$M$2) -> 343.1272 | E12: ='Data Sheet SS'!E13*(1+Supascreen!$M$2) -> 428.909 | F12: ='Data Sheet SS'!F13*(1+Supascreen!$M$2) -> 480.37808 | G12: ='Data Sheet SS'!G13*(1+Supascreen!$M$2) -> 600.4726 | H12: ='Data Sheet SS'!H13*(1+Supascreen!$M$2) -> 686.2544 | I12: ='Data Sheet SS'!I13*(1+Supascreen!$M$2) -> 772.03621 | J12: ='Data Sheet SS'!J13*(1+Supascreen!$M$2) -> 857.81801 | ... R12: ='Data Sheet SS'!R13*(1+Supascreen!$M$2) -> 1544.0724
B13: 1650 | C13: ='Data Sheet SS'!C14*(1+Supascreen!$M$2) -> 274.50176 | D13: ='Data Sheet SS'!D14*(1+Supascreen!$M$2) -> 360.28356 | E13: ='Data Sheet SS'!E14*(1+Supascreen!$M$2) -> 463.22172 | F13: ='Data Sheet SS'!F14*(1+Supascreen!$M$2) -> 549.00352 | G13: ='Data Sheet SS'!G14*(1+Supascreen!$M$2) -> 651.94168 | H13: ='Data Sheet SS'!H14*(1+Supascreen!$M$2) -> 737.72348 | I13: ='Data Sheet SS'!I14*(1+Supascreen!$M$2) -> 840.66165 | J13: ='Data Sheet SS'!J14*(1+Supascreen!$M$2) -> 943.59981 | ... R13: ='Data Sheet SS'!R14*(1+Supascreen!$M$2) -> 1681.3233
B14: 1800 | C14: ='Data Sheet SS'!C15*(1+Supascreen!$M$2) -> 291.65812 | D14: ='Data Sheet SS'!D15*(1+Supascreen!$M$2) -> 394.59628 | E14: ='Data Sheet SS'!E15*(1+Supascreen!$M$2) -> 497.53444 | F14: ='Data Sheet SS'!F15*(1+Supascreen!$M$2) -> 600.4726 | G14: ='Data Sheet SS'!G15*(1+Supascreen!$M$2) -> 703.41076 | H14: ='Data Sheet SS'!H15*(1+Supascreen!$M$2) -> 806.34893 | I14: ='Data Sheet SS'!I15*(1+Supascreen!$M$2) -> 909.28709 | J14: ='Data Sheet SS'!J15*(1+Supascreen!$M$2) -> 1012.2252 | ... R14: ='Data Sheet SS'!R15*(1+Supascreen!$M$2) -> 1818.5742
B15: 1950 | C15: ='Data Sheet SS'!C16*(1+Supascreen!$M$2) -> 308.81448 | D15: ='Data Sheet SS'!D16*(1+Supascreen!$M$2) -> 411.75264 | E15: ='Data Sheet SS'!E16*(1+Supascreen!$M$2) -> 531.84716 | F15: ='Data Sheet SS'!F16*(1+Supascreen!$M$2) -> 634.78532 | G15: ='Data Sheet SS'!G16*(1+Supascreen!$M$2) -> 772.03621 | H15: ='Data Sheet SS'!H16*(1+Supascreen!$M$2) -> 857.81801 | I15: ='Data Sheet SS'!I16*(1+Supascreen!$M$2) -> 960.75617 | J15: ='Data Sheet SS'!J16*(1+Supascreen!$M$2) -> 1098.007 | ... R15: ='Data Sheet SS'!R16*(1+Supascreen!$M$2) -> 1972.9814
B16: 2100 | C16: ='Data Sheet SS'!C17*(1+Supascreen!$M$2) -> 325.97084 | D16: ='Data Sheet SS'!D17*(1+Supascreen!$M$2) -> 446.06536 | E16: ='Data Sheet SS'!E17*(1+Supascreen!$M$2) -> 566.15988 | F16: ='Data Sheet SS'!F17*(1+Supascreen!$M$2) -> 686.2544 | G16: ='Data Sheet SS'!G17*(1+Supascreen!$M$2) -> 806.34893 | H16: ='Data Sheet SS'!H17*(1+Supascreen!$M$2) -> 909.28709 | I16: ='Data Sheet SS'!I17*(1+Supascreen!$M$2) -> 1029.3816 | J16: ='Data Sheet SS'!J17*(1+Supascreen!$M$2) -> 1183.7888 | ... R16: ='Data Sheet SS'!R17*(1+Supascreen!$M$2) -> 2110.2323
B17: 2250 | C17: ='Data Sheet SS'!C18*(1+Supascreen!$M$2) -> 343.1272 | D17: ='Data Sheet SS'!D18*(1+Supascreen!$M$2) -> 480.37808 | E17: ='Data Sheet SS'!E18*(1+Supascreen!$M$2) -> 600.4726 | F17: ='Data Sheet SS'!F18*(1+Supascreen!$M$2) -> 720.56712 | G17: ='Data Sheet SS'!G18*(1+Supascreen!$M$2) -> 840.66165 | H17: ='Data Sheet SS'!H18*(1+Supascreen!$M$2) -> 977.91253 | I17: ='Data Sheet SS'!I18*(1+Supascreen!$M$2) -> 1098.007 | J17: ='Data Sheet SS'!J18*(1+Supascreen!$M$2) -> 1252.4143 | ... R17: ='Data Sheet SS'!R18*(1+Supascreen!$M$2) -> 2264.6395
... B19: 2550 | C19: ='Data Sheet SS'!C20*(1+Supascreen!$M$2) -> 377.43992 | D19: ='Data Sheet SS'!D20*(1+Supascreen!$M$2) -> 514.6908 | E19: ='Data Sheet SS'!E20*(1+Supascreen!$M$2) -> 669.09804 | F19: ='Data Sheet SS'!F20*(1+Supascreen!$M$2) -> 806.34893 | G19: ='Data Sheet SS'!G20*(1+Supascreen!$M$2) -> 943.59981 | H19: ='Data Sheet SS'!H20*(1+Supascreen!$M$2) -> 1098.007 | I19: ='Data Sheet SS'!I20*(1+Supascreen!$M$2) -> 1235.2579 | J19: ='Data Sheet SS'!J20*(1+Supascreen!$M$2) -> 1389.6652 | ... R19: ='Data Sheet SS'!R20*(1+Supascreen!$M$2) -> 2539.1413
L21: Percentage Increase | M21: 0.055
C22: Supascreen Doors
C23: 825 | D23: 875 | E23: 925 | F23: 975 | G23: 1025 | H23: 1075 | I23: 1125 | J23: 1175 | K23: 1225 | L23: 1275 | M23: 1325 | N23: 1375 | O23: 1425 | P23: 1500
B24: 2100 | C24: =(IF('Data Sheet SS'!C24="N/A", "N/A",('Data Sheet SS'!C24*(1+Supascreen!$M$21)))) -> 1081.157 | D24: =(IF('Data Sheet SS'!D24="N/A", "N/A",('Data Sheet SS'!D24*(1+Supascreen!$M$21)))) -> 1086.5627 | E24: =(IF('Data Sheet SS'!E24="N/A", "N/A",('Data Sheet SS'!E24*(1+Supascreen!$M$21)))) -> 1102.7801 | F24: =(IF('Data Sheet SS'!F24="N/A", "N/A",('Data Sheet SS'!F24*(1+Supascreen!$M$21)))) -> 1118.9975 | G24: =(IF('Data Sheet SS'!G24="N/A", "N/A",('Data Sheet SS'!G24*(1+Supascreen!$M$21)))) -> 1151.4322 | H24: =(IF('Data Sheet SS'!H24="N/A", "N/A",('Data Sheet SS'!H24*(1+Supascreen!$M$21)))) -> 1183.8669 | I24: =(IF('Data Sheet SS'!I24="N/A", "N/A",('Data Sheet SS'!I24*(1+Supascreen!$M$21)))) -> 1216.3016 | J24: =(IF('Data Sheet SS'!J24="N/A", "N/A",('Data Sheet SS'!J24*(1+Supascreen!$M$21)))) -> 1248.7363 | ... P24: =(IF('Data Sheet SS'!P24="N/A", "N/A",('Data Sheet SS'!P24*(1+Supascreen!$M$21)))) -> 1540.6487
B25: 2200 | C25: =(IF('Data Sheet SS'!C25="N/A", "N/A",('Data Sheet SS'!C25*(1+Supascreen!$M$21)))) -> 1102.7801 | D25: =(IF('Data Sheet SS'!D25="N/A", "N/A",('Data Sheet SS'!D25*(1+Supascreen!$M$21)))) -> 1119.7697 | E25: =(IF('Data Sheet SS'!E25="N/A", "N/A",('Data Sheet SS'!E25*(1+Supascreen!$M$21)))) -> 1135.2148 | F25: =(IF('Data Sheet SS'!F25="N/A", "N/A",('Data Sheet SS'!F25*(1+Supascreen!$M$21)))) -> 1151.4322 | G25: =(IF('Data Sheet SS'!G25="N/A", "N/A",('Data Sheet SS'!G25*(1+Supascreen!$M$21)))) -> 1183.8669 | H25: =(IF('Data Sheet SS'!H25="N/A", "N/A",('Data Sheet SS'!H25*(1+Supascreen!$M$21)))) -> 1216.3016 | I25: =(IF('Data Sheet SS'!I25="N/A", "N/A",('Data Sheet SS'!I25*(1+Supascreen!$M$21)))) -> 1248.7363 | J25: =(IF('Data Sheet SS'!J25="N/A", "N/A",('Data Sheet SS'!J25*(1+Supascreen!$M$21)))) -> 1281.171 | ... P25: =(IF('Data Sheet SS'!P25="N/A", "N/A",('Data Sheet SS'!P25*(1+Supascreen!$M$21)))) -> 1605.5181
B26: 2300 | C26: =(IF('Data Sheet SS'!C26="N/A", "N/A",('Data Sheet SS'!C26*(1+Supascreen!$M$21)))) -> 1135.2148 | D26: =(IF('Data Sheet SS'!D26="N/A", "N/A",('Data Sheet SS'!D26*(1+Supascreen!$M$21)))) -> 1142.9374 | E26: =(IF('Data Sheet SS'!E26="N/A", "N/A",('Data Sheet SS'!E26*(1+Supascreen!$M$21)))) -> 1151.4322 | F26: =(IF('Data Sheet SS'!F26="N/A", "N/A",('Data Sheet SS'!F26*(1+Supascreen!$M$21)))) -> 1183.8669 | G26: =(IF('Data Sheet SS'!G26="N/A", "N/A",('Data Sheet SS'!G26*(1+Supascreen!$M$21)))) -> 1216.3016 | H26: =(IF('Data Sheet SS'!H26="N/A", "N/A",('Data Sheet SS'!H26*(1+Supascreen!$M$21)))) -> 1248.7363 | I26: =(IF('Data Sheet SS'!I26="N/A", "N/A",('Data Sheet SS'!I26*(1+Supascreen!$M$21)))) -> 1281.171 | J26: =(IF('Data Sheet SS'!J26="N/A", "N/A",('Data Sheet SS'!J26*(1+Supascreen!$M$21)))) -> 1313.6057 | ... P26: =(IF('Data Sheet SS'!P26="N/A", "N/A",('Data Sheet SS'!P26*(1+Supascreen!$M$21)))) -> 1670.3875
B27: 2400 | C27: =(IF('Data Sheet SS'!C27="N/A", "N/A",('Data Sheet SS'!C27*(1+Supascreen!$M$21)))) -> 1151.4322 | D27: =(IF('Data Sheet SS'!D27="N/A", "N/A",('Data Sheet SS'!D27*(1+Supascreen!$M$21)))) -> 1167.6495 | E27: =(IF('Data Sheet SS'!E27="N/A", "N/A",('Data Sheet SS'!E27*(1+Supascreen!$M$21)))) -> 1183.8669 | F27: =(IF('Data Sheet SS'!F27="N/A", "N/A",('Data Sheet SS'!F27*(1+Supascreen!$M$21)))) -> 1216.3016 | G27: =(IF('Data Sheet SS'!G27="N/A", "N/A",('Data Sheet SS'!G27*(1+Supascreen!$M$21)))) -> 1248.7363 | H27: =(IF('Data Sheet SS'!H27="N/A", "N/A",('Data Sheet SS'!H27*(1+Supascreen!$M$21)))) -> 1281.171 | I27: =(IF('Data Sheet SS'!I27="N/A", "N/A",('Data Sheet SS'!I27*(1+Supascreen!$M$21)))) -> 1313.6057 | J27: =(IF('Data Sheet SS'!J27="N/A", "N/A",('Data Sheet SS'!J27*(1+Supascreen!$M$21)))) -> 1346.0404 | ... P27: =(IF('Data Sheet SS'!P27="N/A", "N/A",('Data Sheet SS'!P27*(1+Supascreen!$M$21)))) -> 1735.2569
B28: 2500 | C28: =(IF('Data Sheet SS'!C28="N/A", "N/A",('Data Sheet SS'!C28*(1+Supascreen!$M$21)))) -> 1183.8669 | D28: =(IF('Data Sheet SS'!D28="N/A", "N/A",('Data Sheet SS'!D28*(1+Supascreen!$M$21)))) -> 1200.0842 | E28: =(IF('Data Sheet SS'!E28="N/A", "N/A",('Data Sheet SS'!E28*(1+Supascreen!$M$21)))) -> 1216.3016 | F28: =(IF('Data Sheet SS'!F28="N/A", "N/A",('Data Sheet SS'!F28*(1+Supascreen!$M$21)))) -> 1248.7363 | G28: =(IF('Data Sheet SS'!G28="N/A", "N/A",('Data Sheet SS'!G28*(1+Supascreen!$M$21)))) -> 1281.171 | H28: =(IF('Data Sheet SS'!H28="N/A", "N/A",('Data Sheet SS'!H28*(1+Supascreen!$M$21)))) -> 1313.6057 | I28: =(IF('Data Sheet SS'!I28="N/A", "N/A",('Data Sheet SS'!I28*(1+Supascreen!$M$21)))) -> 1346.0404 | J28: =(IF('Data Sheet SS'!J28="N/A", "N/A",('Data Sheet SS'!J28*(1+Supascreen!$M$21)))) -> 1378.4751 | ... P28: =(IF('Data Sheet SS'!P28="N/A", "N/A",('Data Sheet SS'!P28*(1+Supascreen!$M$21)))) -> 1800.1263
B29: 2600 | C29: =(IF('Data Sheet SS'!C29="N/A", "N/A",('Data Sheet SS'!C29*(1+Supascreen!$M$21)))) -> 1216.3016 | D29: =(IF('Data Sheet SS'!D29="N/A", "N/A",('Data Sheet SS'!D29*(1+Supascreen!$M$21)))) -> 1248.7363 | E29: =(IF('Data Sheet SS'!E29="N/A", "N/A",('Data Sheet SS'!E29*(1+Supascreen!$M$21)))) -> 1281.171 | F29: =(IF('Data Sheet SS'!F29="N/A", "N/A",('Data Sheet SS'!F29*(1+Supascreen!$M$21)))) -> 1313.6057 | G29: =(IF('Data Sheet SS'!G29="N/A", "N/A",('Data Sheet SS'!G29*(1+Supascreen!$M$21)))) -> 1346.0404 | H29: =(IF('Data Sheet SS'!H29="N/A", "N/A",('Data Sheet SS'!H29*(1+Supascreen!$M$21)))) -> 1378.4751 | I29: =(IF('Data Sheet SS'!I29="N/A", "N/A",('Data Sheet SS'!I29*(1+Supascreen!$M$21)))) -> 1410.9098 | J29: =(IF('Data Sheet SS'!J29="N/A", "N/A",('Data Sheet SS'!J29*(1+Supascreen!$M$21)))) -> 1475.7793 | ... P29: =(IF('Data Sheet SS'!P29="N/A", "N/A",('Data Sheet SS'!P29*(1+Supascreen!$M$21)))) -> 1864.9958
B31: Note: ALL price exclude GST

Sheet Data Sheet SS
A1: Supply and Install Data File
A3: DO NOT USE FOR PRICING
C5: Superscreen Windows
C6: 300 | D6: 450 | E6: 600 | F6: 750 | G6: 900 | H6: 1050 | I6: 1200 | J6: 1350 | K6: 1500 | L6: 1650 | M6: 1800 | N6: 1950 | O6: 2100 | P6: 2250 | Q6: 2400 | R6: 2550
B7: 600 | C7: 146.35757 | D7: 178.88148 | E7: 211.40539 | F7: 243.92929 | G7: 276.4532 | H7: 308.9771 | I7: 341.50101 | J7: 390.28687 | K7: 471.59663 | L7: 455.33468 | M7: 487.85858 | N7: 520.38249 | O7: 552.90639 | P7: 585.4303 | Q7: 617.9542 | R7: 650.47811
B8: 750 | C8: 162.61953 | D8: 211.40539 | E8: 243.92929 | F8: 292.71515 | G8: 325.23905 | H8: 357.76296 | I8: 406.54882 | J8: 471.59663 | K8: 504.12053 | L8: 536.64444 | M8: 585.4303 | N8: 617.9542 | O8: 666.74006 | P8: 699.26397 | Q8: 748.04982 | R8: 780.57373
B9: 900 | C9: 178.88148 | D9: 243.92929 | E9: 276.4532 | F9: 325.23905 | G9: 374.02491 | H9: 422.81077 | I9: 471.59663 | J9: 536.64444 | K9: 585.4303 | L9: 634.21616 | M9: 683.00201 | N9: 731.78787 | O9: 748.04982 | P9: 813.09764 | Q9: 878.14545 | R9: 910.66935
B10: 1050 | C10: 195.14343 | D10: 260.19124 | E10: 308.9771 | F10: 357.76296 | G10: 422.81077 | H10: 471.59663 | I10: 536.64444 | J10: 601.69225 | K10: 666.74006 | L10: 715.52592 | M10: 780.57373 | N10: 829.35959 | O10: 878.14545 | P10: 943.19326 | Q10: 991.97912 | R10: 1057.0269
B11: 1200 | C11: 211.40539 | D11: 276.4532 | E11: 341.50101 | F11: 406.54882 | G11: 471.59663 | H11: 536.64444 | I11: 601.69225 | J11: 666.74006 | K11: 748.04982 | L11: 796.83568 | M11: 878.14545 | N11: 926.9313 | O11: 991.97912 | P11: 1057.0269 | Q11: 1122.0747 | R11: 1187.1225
B12: 1350 | C12: 227.66734 | D12: 308.9771 | E12: 374.02491 | F12: 439.07272 | G12: 520.38249 | H12: 585.4303 | I12: 666.74006 | J12: 748.04982 | K12: 813.09764 | L12: 894.4074 | M12: 959.45521 | N12: 1040.765 | O12: 1105.8128 | P12: 1187.1225 | Q12: 1252.1704 | R12: 1317.2182
B13: 1500 | C13: 243.92929 | D13: 325.23905 | E13: 406.54882 | F13: 455.33468 | G13: 569.16834 | H13: 650.47811 | I13: 731.78787 | J13: 813.09764 | K13: 894.4074 | L13: 975.71716 | M13: 1057.0269 | N13: 1138.3367 | O13: 1219.6465 | P13: 1300.9562 | Q13: 1382.266 | R13: 1463.5757
B14: 1650 | C14: 260.19124 | D14: 341.50101 | E14: 439.07272 | F14: 520.38249 | G14: 617.9542 | H14: 699.26397 | I14: 796.83568 | J14: 894.4074 | K14: 975.71716 | L14: 1073.2889 | M14: 1154.5986 | N14: 1235.9084 | O14: 1333.4801 | P14: 1414.7899 | Q14: 1512.3616 | R14: 1593.6714
B15: 1800 | C15: 276.4532 | D15: 374.02491 | E15: 471.59663 | F15: 569.16834 | G15: 666.74006 | H15: 764.31178 | I15: 861.88349 | J15: 959.45521 | K15: 1057.0269 | L15: 1154.5986 | M15: 1252.1704 | N15: 1349.7421 | O15: 1447.3138 | P15: 1544.8855 | Q15: 1626.1953 | R15: 1723.767
B16: 1950 | C16: 292.71515 | D16: 390.28687 | E16: 504.12053 | F16: 601.69225 | G16: 731.78787 | H16: 813.09764 | I16: 910.66935 | J16: 1040.765 | K16: 1138.3367 | L16: 1235.9084 | M16: 1349.7421 | N16: 1447.3138 | O16: 1561.1475 | P16: 1658.7192 | Q16: 1756.2909 | R16: 1870.1246
B17: 2100 | C17: 308.9771 | D17: 422.81077 | E17: 536.64444 | F17: 650.47811 | G17: 764.31178 | H17: 861.88349 | I17: 975.71716 | J17: 1122.0747 | K17: 1219.6465 | L17: 1333.4801 | M17: 1447.3138 | N17: 1561.1475 | O17: 1658.7192 | P17: 1772.5528 | Q17: 1886.3865 | R17: 2000.2202
B18: 2250 | C18: 325.23905 | D18: 455.33468 | E18: 569.16834 | F18: 683.00201 | G18: 796.83568 | H18: 926.9313 | I18: 1040.765 | J18: 1187.1225 | K18: 1300.9562 | L18: 1414.7899 | M18: 1544.8855 | N18: 1658.7192 | O18: 1772.5528 | P18: 1902.6485 | Q18: 2016.4821 | R18: 2146.5778
... B20: 2550 | C20: 357.76296 | D20: 487.85858 | E20: 634.21616 | F20: 764.31178 | G20: 894.4074 | H20: 1040.765 | I20: 1170.8606 | J20: 1317.2182 | K20: 1463.5757 | L20: 1593.6714 | M20: 1723.767 | N20: 1870.1246 | O20: 2000.2202 | P20: 2146.5778 | Q20: 2276.6734 | R20: 2406.769
C22: Superscreen Doors
C23: 825 | D23: 875 | E23: 925 | F23: 975 | G23: 1025 | H23: 1075 | I23: 1125 | J23: 1175 | K23: 1225 | L23: 1275 | M23: 1325 | N23: 1375 | O23: 1425 | P23: 1500
B24: 2100 | C24: 966.78616 | D24: 971.62009 | E24: 986.12188 | F24: 1000.6237 | G24: 1029.6273 | H24: 1058.6308 | I24: 1087.6344 | J24: 1116.638 | K24: 1174.6452 | L24: 1189.147 | M24: 1218.1506 | N24: 1247.1541 | O24: 1276.1577 | P24: 1377.6703
B25: 2200 | C25: 986.12188 | D25: 1001.3142 | E25: 1015.1255 | F25: 1029.6273 | G25: 1058.6308 | H25: 1087.6344 | I25: 1116.638 | J25: 1145.6416 | K25: 1203.6488 | L25: 1218.1506 | M25: 1247.1541 | N25: 1276.1577 | O25: 1305.1613 | P25: 1435.6774
B26: 2300 | C26: 1015.1255 | D26: 1022.0311 | E26: 1029.6273 | F26: 1058.6308 | G26: 1087.6344 | H26: 1116.638 | I26: 1145.6416 | J26: 1174.6452 | K26: 1234 | L26: 1232.6524 | M26: 1276.1577 | N26: 1305.1613 | O26: 1334.1649 | P26: 1493.6846
B27: 2400 | C27: 1029.6273 | D27: 1044.1291 | E27: 1058.6308 | F27: 1087.6344 | G27: 1116.638 | H27: 1145.6416 | I27: 1174.6452 | J27: 1203.6488 | K27: 1263 | L27: 1276.1577 | M27: 1305.1613 | N27: 1334.1649 | O27: 1363.1685 | P27: 1551.6918
B28: 2500 | C28: 1058.6308 | D28: 1073.1326 | E28: 1087.6344 | F28: 1116.638 | G28: 1145.6416 | H28: 1174.6452 | I28: 1203.6488 | J28: 1232.6524 | K28: 1290.6595 | L28: 1305.1613 | M28: 1334.1649 | N28: 1363.1685 | O28: 1392.1721 | P28: 1609.699
B29: 2600 | C29: 1087.6344 | D29: 1116.638 | E29: 1145.6416 | F29: 1174.6452 | G29: 1203.6488 | H29: 1232.6524 | I29: 1261.6559 | J29: 1319.6631 | K29: 1334.1649 | L29: 1363.1685 | M29: 1392.1721 | N29: 1421.1757 | O29: 1450.1792 | P29: 1667.7061

Sheet  IntrudaGuard
A1: Supply and Install IntrudaGuard
G2: Pricing as at | H2: 46054 | L2: Percentage Increase | M2: 0.055
C4: IntrudaGuard Windows
C5: 300 | D5: 450 | E5: 600 | F5: 750 | G5: 900 | H5: 1050 | I5: 1200 | J5: 1350 | K5: 1500 | L5: 1650 | M5: 1800 | N5: 1950 | O5: 2100 | P5: 2250 | Q5: 2400 | R5: 2550
B6: 600 | C6: =('Date Sheet IG '!C8)*(1+' IntrudaGuard'!$M$2) -> 129.73799 | D6: =('Date Sheet IG '!D8)*(1+' IntrudaGuard'!$M$2) -> 158.56866 | E6: =('Date Sheet IG '!E8)*(1+' IntrudaGuard'!$M$2) -> 187.39932 | F6: =('Date Sheet IG '!F8)*(1+' IntrudaGuard'!$M$2) -> 216.22999 | G6: =('Date Sheet IG '!G8)*(1+' IntrudaGuard'!$M$2) -> 245.06065 | H6: =('Date Sheet IG '!H8)*(1+' IntrudaGuard'!$M$2) -> 273.89132 | I6: =('Date Sheet IG '!I8)*(1+' IntrudaGuard'!$M$2) -> 302.72198 | J6: =('Date Sheet IG '!J8)*(1+' IntrudaGuard'!$M$2) -> 345.96798 | ... R6: =('Date Sheet IG '!R8)*(1+' IntrudaGuard'!$M$2) -> 576.6133
B7: 750 | C7: =('Date Sheet IG '!C9)*(1+' IntrudaGuard'!$M$2) -> 144.15333 | D7: =('Date Sheet IG '!D9)*(1+' IntrudaGuard'!$M$2) -> 187.39932 | E7: =('Date Sheet IG '!E9)*(1+' IntrudaGuard'!$M$2) -> 216.22999 | F7: =('Date Sheet IG '!F9)*(1+' IntrudaGuard'!$M$2) -> 259.47599 | G7: =('Date Sheet IG '!G9)*(1+' IntrudaGuard'!$M$2) -> 288.30665 | H7: =('Date Sheet IG '!H9)*(1+' IntrudaGuard'!$M$2) -> 317.13732 | I7: =('Date Sheet IG '!I9)*(1+' IntrudaGuard'!$M$2) -> 360.38331 | J7: =('Date Sheet IG '!J9)*(1+' IntrudaGuard'!$M$2) -> 418.04464 | ... R7: =('Date Sheet IG '!R9)*(1+' IntrudaGuard'!$M$2) -> 691.93596
B8: 900 | C8: =('Date Sheet IG '!C10)*(1+' IntrudaGuard'!$M$2) -> 158.56866 | D8: =('Date Sheet IG '!D10)*(1+' IntrudaGuard'!$M$2) -> 216.22999 | E8: =('Date Sheet IG '!E10)*(1+' IntrudaGuard'!$M$2) -> 245.06065 | F8: =('Date Sheet IG '!F10)*(1+' IntrudaGuard'!$M$2) -> 288.30665 | G8: =('Date Sheet IG '!G10)*(1+' IntrudaGuard'!$M$2) -> 331.55265 | H8: =('Date Sheet IG '!H10)*(1+' IntrudaGuard'!$M$2) -> 374.79865 | I8: =('Date Sheet IG '!I10)*(1+' IntrudaGuard'!$M$2) -> 418.04464 | J8: =('Date Sheet IG '!J10)*(1+' IntrudaGuard'!$M$2) -> 475.70597 | ... R8: =('Date Sheet IG '!R10)*(1+' IntrudaGuard'!$M$2) -> 807.25862
B9: 1050 | C9: =('Date Sheet IG '!C11)*(1+' IntrudaGuard'!$M$2) -> 172.98399 | D9: =('Date Sheet IG '!D11)*(1+' IntrudaGuard'!$M$2) -> 230.64532 | E9: =('Date Sheet IG '!E11)*(1+' IntrudaGuard'!$M$2) -> 273.89132 | F9: =('Date Sheet IG '!F11)*(1+' IntrudaGuard'!$M$2) -> 317.13732 | G9: =('Date Sheet IG '!G11)*(1+' IntrudaGuard'!$M$2) -> 374.79865 | H9: =('Date Sheet IG '!H11)*(1+' IntrudaGuard'!$M$2) -> 418.04464 | I9: =('Date Sheet IG '!I11)*(1+' IntrudaGuard'!$M$2) -> 475.70597 | J9: =('Date Sheet IG '!J11)*(1+' IntrudaGuard'!$M$2) -> 533.3673 | ... R9: =('Date Sheet IG '!R11)*(1+' IntrudaGuard'!$M$2) -> 936.99662
B10: 1200 | C10: =('Date Sheet IG '!C12)*(1+' IntrudaGuard'!$M$2) -> 187.39932 | D10: =('Date Sheet IG '!D12)*(1+' IntrudaGuard'!$M$2) -> 245.06065 | E10: =('Date Sheet IG '!E12)*(1+' IntrudaGuard'!$M$2) -> 302.72198 | F10: =('Date Sheet IG '!F12)*(1+' IntrudaGuard'!$M$2) -> 360.38331 | G10: =('Date Sheet IG '!G12)*(1+' IntrudaGuard'!$M$2) -> 418.04464 | H10: =('Date Sheet IG '!H12)*(1+' IntrudaGuard'!$M$2) -> 475.70597 | I10: =('Date Sheet IG '!I12)*(1+' IntrudaGuard'!$M$2) -> 533.3673 | J10: =('Date Sheet IG '!J12)*(1+' IntrudaGuard'!$M$2) -> 591.02863 | ... R10: =('Date Sheet IG '!R12)*(1+' IntrudaGuard'!$M$2) -> 1052.3193
B11: 1350 | C11: =('Date Sheet IG '!C13)*(1+' IntrudaGuard'!$M$2) -> 201.81466 | D11: =('Date Sheet IG '!D13)*(1+' IntrudaGuard'!$M$2) -> 273.89132 | E11: =('Date Sheet IG '!E13)*(1+' IntrudaGuard'!$M$2) -> 331.55265 | F11: =('Date Sheet IG '!F13)*(1+' IntrudaGuard'!$M$2) -> 389.21398 | G11: =('Date Sheet IG '!G13)*(1+' IntrudaGuard'!$M$2) -> 461.29064 | H11: =('Date Sheet IG '!H13)*(1+' IntrudaGuard'!$M$2) -> 518.95197 | I11: =('Date Sheet IG '!I13)*(1+' IntrudaGuard'!$M$2) -> 591.02863 | J11: =('Date Sheet IG '!J13)*(1+' IntrudaGuard'!$M$2) -> 663.1053 | ... R11: =('Date Sheet IG '!R13)*(1+' IntrudaGuard'!$M$2) -> 1167.6419
B12: 1500 | C12: =('Date Sheet IG '!C14)*(1+' IntrudaGuard'!$M$2) -> 216.22999 | D12: =('Date Sheet IG '!D14)*(1+' IntrudaGuard'!$M$2) -> 288.30665 | E12: =('Date Sheet IG '!E14)*(1+' IntrudaGuard'!$M$2) -> 360.38331 | F12: =('Date Sheet IG '!F14)*(1+' IntrudaGuard'!$M$2) -> 403.62931 | G12: =('Date Sheet IG '!G14)*(1+' IntrudaGuard'!$M$2) -> 504.53664 | H12: =('Date Sheet IG '!H14)*(1+' IntrudaGuard'!$M$2) -> 576.6133 | I12: =('Date Sheet IG '!I14)*(1+' IntrudaGuard'!$M$2) -> 648.68996 | J12: =('Date Sheet IG '!J14)*(1+' IntrudaGuard'!$M$2) -> 720.76663 | ... R12: =('Date Sheet IG '!R14)*(1+' IntrudaGuard'!$M$2) -> 1297.3799
B13: 1650 | C13: =('Date Sheet IG '!C15)*(1+' IntrudaGuard'!$M$2) -> 230.64532 | D13: =('Date Sheet IG '!D15)*(1+' IntrudaGuard'!$M$2) -> 302.72198 | E13: =('Date Sheet IG '!E15)*(1+' IntrudaGuard'!$M$2) -> 389.21398 | F13: =('Date Sheet IG '!F15)*(1+' IntrudaGuard'!$M$2) -> 461.29064 | G13: =('Date Sheet IG '!G15)*(1+' IntrudaGuard'!$M$2) -> 547.78264 | H13: =('Date Sheet IG '!H15)*(1+' IntrudaGuard'!$M$2) -> 619.8593 | I13: =('Date Sheet IG '!I15)*(1+' IntrudaGuard'!$M$2) -> 706.35129 | J13: =('Date Sheet IG '!J15)*(1+' IntrudaGuard'!$M$2) -> 792.84329 | ... R13: =('Date Sheet IG '!R15)*(1+' IntrudaGuard'!$M$2) -> 1412.7026
B14: 1800 | C14: =('Date Sheet IG '!C16)*(1+' IntrudaGuard'!$M$2) -> 245.06065 | D14: =('Date Sheet IG '!D16)*(1+' IntrudaGuard'!$M$2) -> 331.55265 | E14: =('Date Sheet IG '!E16)*(1+' IntrudaGuard'!$M$2) -> 418.04464 | F14: =('Date Sheet IG '!F16)*(1+' IntrudaGuard'!$M$2) -> 504.53664 | G14: =('Date Sheet IG '!G16)*(1+' IntrudaGuard'!$M$2) -> 591.02863 | H14: =('Date Sheet IG '!H16)*(1+' IntrudaGuard'!$M$2) -> 677.52063 | I14: =('Date Sheet IG '!I16)*(1+' IntrudaGuard'!$M$2) -> 764.01263 | J14: =('Date Sheet IG '!J16)*(1+' IntrudaGuard'!$M$2) -> 850.50462 | ... R14: =('Date Sheet IG '!R16)*(1+' IntrudaGuard'!$M$2) -> 1528.0253
B15: 1950 | C15: =('Date Sheet IG '!C17)*(1+' IntrudaGuard'!$M$2) -> 259.47599 | D15: =('Date Sheet IG '!D17)*(1+' IntrudaGuard'!$M$2) -> 345.96798 | E15: =('Date Sheet IG '!E17)*(1+' IntrudaGuard'!$M$2) -> 446.87531 | F15: =('Date Sheet IG '!F17)*(1+' IntrudaGuard'!$M$2) -> 533.3673 | G15: =('Date Sheet IG '!G17)*(1+' IntrudaGuard'!$M$2) -> 648.68996 | H15: =('Date Sheet IG '!H17)*(1+' IntrudaGuard'!$M$2) -> 720.76663 | I15: =('Date Sheet IG '!I17)*(1+' IntrudaGuard'!$M$2) -> 807.25862 | J15: =('Date Sheet IG '!J17)*(1+' IntrudaGuard'!$M$2) -> 922.58128 | ... R15: =('Date Sheet IG '!R17)*(1+' IntrudaGuard'!$M$2) -> 1657.7632
B16: 2100 | C16: =('Date Sheet IG '!C18)*(1+' IntrudaGuard'!$M$2) -> 273.89132 | D16: =('Date Sheet IG '!D18)*(1+' IntrudaGuard'!$M$2) -> 374.79865 | E16: =('Date Sheet IG '!E18)*(1+' IntrudaGuard'!$M$2) -> 475.70597 | F16: =('Date Sheet IG '!F18)*(1+' IntrudaGuard'!$M$2) -> 576.6133 | G16: =('Date Sheet IG '!G18)*(1+' IntrudaGuard'!$M$2) -> 677.52063 | H16: =('Date Sheet IG '!H18)*(1+' IntrudaGuard'!$M$2) -> 764.01263 | I16: =('Date Sheet IG '!I18)*(1+' IntrudaGuard'!$M$2) -> 864.91995 | J16: =('Date Sheet IG '!J18)*(1+' IntrudaGuard'!$M$2) -> 994.65795 | ... R16: =('Date Sheet IG '!R18)*(1+' IntrudaGuard'!$M$2) -> 1773.0859
B17: 2250 | C17: =('Date Sheet IG '!C19)*(1+' IntrudaGuard'!$M$2) -> 288.30665 | D17: =('Date Sheet IG '!D19)*(1+' IntrudaGuard'!$M$2) -> 403.62931 | E17: =('Date Sheet IG '!E19)*(1+' IntrudaGuard'!$M$2) -> 504.53664 | F17: =('Date Sheet IG '!F19)*(1+' IntrudaGuard'!$M$2) -> 605.44397 | G17: =('Date Sheet IG '!G19)*(1+' IntrudaGuard'!$M$2) -> 706.35129 | H17: =('Date Sheet IG '!H19)*(1+' IntrudaGuard'!$M$2) -> 821.67396 | I17: =('Date Sheet IG '!I19)*(1+' IntrudaGuard'!$M$2) -> 922.58128 | J17: =('Date Sheet IG '!J19)*(1+' IntrudaGuard'!$M$2) -> 1052.3193 | ... R17: =('Date Sheet IG '!R19)*(1+' IntrudaGuard'!$M$2) -> 1902.8239
... B19: 2550 | C19: =('Date Sheet IG '!C21)*(1+' IntrudaGuard'!$M$2) -> 317.13732 | D19: =('Date Sheet IG '!D21)*(1+' IntrudaGuard'!$M$2) -> 432.45998 | E19: =('Date Sheet IG '!E21)*(1+' IntrudaGuard'!$M$2) -> 562.19797 | F19: =('Date Sheet IG '!F21)*(1+' IntrudaGuard'!$M$2) -> 677.52063 | G19: =('Date Sheet IG '!G21)*(1+' IntrudaGuard'!$M$2) -> 792.84329 | H19: =('Date Sheet IG '!H21)*(1+' IntrudaGuard'!$M$2) -> 922.58128 | I19: =('Date Sheet IG '!I21)*(1+' IntrudaGuard'!$M$2) -> 1037.9039 | J19: =('Date Sheet IG '!J21)*(1+' IntrudaGuard'!$M$2) -> 1167.6419 | ... R19: =('Date Sheet IG '!R21)*(1+' IntrudaGuard'!$M$2) -> 2133.4692
L21: Percentage Increase | M21: 0.055
C22: IntrudaGuard Doors
C23: 825 | D23: 875 | E23: 925 | F23: 975 | G23: 1025 | H23: 1075 | I23: 1125 | J23: 1175 | K23: 1225 | L23: 1275 | M23: 1325 | N23: 1375 | O23: 1425 | P23: 1500
B24: 2100 | C24: =('Date Sheet IG '!C25)*(1+' IntrudaGuard'!$M$21) -> 968.97337 | D24: =('Date Sheet IG '!D25)*(1+' IntrudaGuard'!$M$21) -> 983.34374 | E24: =('Date Sheet IG '!E25)*(1+' IntrudaGuard'!$M$21) -> 997.71411 | F24: =('Date Sheet IG '!F25)*(1+' IntrudaGuard'!$M$21) -> 1012.0845 | G24: =('Date Sheet IG '!G25)*(1+' IntrudaGuard'!$M$21) -> 1040.8252 | H24: =('Date Sheet IG '!H25)*(1+' IntrudaGuard'!$M$21) -> 1069.5659 | I24: =('Date Sheet IG '!I25)*(1+' IntrudaGuard'!$M$21) -> 1098.3067 | J24: =('Date Sheet IG '!J25)*(1+' IntrudaGuard'!$M$21) -> 1127.0474 | ... P24: =('Date Sheet IG '!P25)*(1+' IntrudaGuard'!$M$21) -> 1385.714
B25: 2200 | C25: =('Date Sheet IG '!C26)*(1+' IntrudaGuard'!$M$21) -> 997.71411 | D25: =('Date Sheet IG '!D26)*(1+' IntrudaGuard'!$M$21) -> 968.97337 | E25: =('Date Sheet IG '!E26)*(1+' IntrudaGuard'!$M$21) -> 1026.4548 | F25: =('Date Sheet IG '!F26)*(1+' IntrudaGuard'!$M$21) -> 1040.8252 | G25: =('Date Sheet IG '!G26)*(1+' IntrudaGuard'!$M$21) -> 1069.5659 | H25: =('Date Sheet IG '!H26)*(1+' IntrudaGuard'!$M$21) -> 1098.3067 | I25: =('Date Sheet IG '!I26)*(1+' IntrudaGuard'!$M$21) -> 1127.0474 | J25: =('Date Sheet IG '!J26)*(1+' IntrudaGuard'!$M$21) -> 1155.7882 | ... P25: =('Date Sheet IG '!P26)*(1+' IntrudaGuard'!$M$21) -> 1443.1955
B26: 2300 | C26: =('Date Sheet IG '!C27)*(1+' IntrudaGuard'!$M$21) -> 1026.4548 | D26: =('Date Sheet IG '!D27)*(1+' IntrudaGuard'!$M$21) -> 997.71411 | E26: =('Date Sheet IG '!E27)*(1+' IntrudaGuard'!$M$21) -> 1040.8252 | F26: =('Date Sheet IG '!F27)*(1+' IntrudaGuard'!$M$21) -> 1069.5659 | G26: =('Date Sheet IG '!G27)*(1+' IntrudaGuard'!$M$21) -> 1098.3067 | H26: =('Date Sheet IG '!H27)*(1+' IntrudaGuard'!$M$21) -> 1127.0474 | I26: =('Date Sheet IG '!I27)*(1+' IntrudaGuard'!$M$21) -> 1155.7882 | J26: =('Date Sheet IG '!J27)*(1+' IntrudaGuard'!$M$21) -> 1184.5289 | ... P26: =('Date Sheet IG '!P27)*(1+' IntrudaGuard'!$M$21) -> 1500.677
B27: 2400 | C27: =('Date Sheet IG '!C28)*(1+' IntrudaGuard'!$M$21) -> 1040.8252 | D27: =('Date Sheet IG '!D28)*(1+' IntrudaGuard'!$M$21) -> 1055.1956 | E27: =('Date Sheet IG '!E28)*(1+' IntrudaGuard'!$M$21) -> 1069.5659 | F27: =('Date Sheet IG '!F28)*(1+' IntrudaGuard'!$M$21) -> 1098.3067 | G27: =('Date Sheet IG '!G28)*(1+' IntrudaGuard'!$M$21) -> 1127.0474 | H27: =('Date Sheet IG '!H28)*(1+' IntrudaGuard'!$M$21) -> 1155.7882 | I27: =('Date Sheet IG '!I28)*(1+' IntrudaGuard'!$M$21) -> 1184.5289 | J27: =('Date Sheet IG '!J28)*(1+' IntrudaGuard'!$M$21) -> 1213.2696 | ... P27: =('Date Sheet IG '!P28)*(1+' IntrudaGuard'!$M$21) -> 1558.1585
B28: 2500 | C28: =('Date Sheet IG '!C29)*(1+' IntrudaGuard'!$M$21) -> 1069.5659 | D28: =('Date Sheet IG '!D29)*(1+' IntrudaGuard'!$M$21) -> 1083.9363 | E28: =('Date Sheet IG '!E29)*(1+' IntrudaGuard'!$M$21) -> 1098.3067 | F28: =('Date Sheet IG '!F29)*(1+' IntrudaGuard'!$M$21) -> 1127.0474 | G28: =('Date Sheet IG '!G29)*(1+' IntrudaGuard'!$M$21) -> 1155.7882 | H28: =('Date Sheet IG '!H29)*(1+' IntrudaGuard'!$M$21) -> 1184.5289 | I28: =('Date Sheet IG '!I29)*(1+' IntrudaGuard'!$M$21) -> 1213.2696 | J28: =('Date Sheet IG '!J29)*(1+' IntrudaGuard'!$M$21) -> 1242.0104 | ... P28: =('Date Sheet IG '!P29)*(1+' IntrudaGuard'!$M$21) -> 1615.6399
B29: 2600 | C29: =('Date Sheet IG '!C30)*(1+' IntrudaGuard'!$M$21) -> 1098.3067 | D29: =('Date Sheet IG '!D30)*(1+' IntrudaGuard'!$M$21) -> 1127.0474 | E29: =('Date Sheet IG '!E30)*(1+' IntrudaGuard'!$M$21) -> 1155.7882 | F29: =('Date Sheet IG '!F30)*(1+' IntrudaGuard'!$M$21) -> 1184.5289 | G29: =('Date Sheet IG '!G30)*(1+' IntrudaGuard'!$M$21) -> 1213.2696 | H29: =('Date Sheet IG '!H30)*(1+' IntrudaGuard'!$M$21) -> 1242.0104 | I29: =('Date Sheet IG '!I30)*(1+' IntrudaGuard'!$M$21) -> 1270.7511 | J29: =('Date Sheet IG '!J30)*(1+' IntrudaGuard'!$M$21) -> 1328.2326 | ... P29: =('Date Sheet IG '!P30)*(1+' IntrudaGuard'!$M$21) -> 1673.1214
B31: Note: ALL price exclude GST

Sheet Date Sheet IG 
A1: Supply and Install Data File
A3: DO NOT USE FOR PRICING
C6: IntrudaGuard Windows
C7: 300 | D7: 450 | E7: 600 | F7: 750 | G7: 900 | H7: 1050 | I7: 1200 | J7: 1350 | K7: 1500 | L7: 1650 | M7: 1800 | N7: 1950 | O7: 2100 | P7: 2250 | Q7: 2400 | R7: 2550
B8: 600 | C8: 114.92935 | D8: 140.4692 | E8: 166.00906 | F8: 191.54891 | G8: 217.08877 | H8: 242.62862 | I8: 268.16848 | J8: 306.47826 | K8: 370.32789 | L8: 357.55797 | M8: 383.09782 | N8: 408.63768 | O8: 434.17753 | P8: 459.71739 | Q8: 485.25724 | R8: 510.7971
B9: 750 | C9: 127.69927 | D9: 166.00906 | E9: 191.54891 | F9: 229.85869 | G9: 255.39855 | H9: 280.9384 | I9: 319.24819 | J9: 370.32789 | K9: 395.86775 | L9: 421.4076 | M9: 459.71739 | N9: 485.25724 | O9: 523.56702 | P9: 549.10688 | Q9: 587.41666 | R9: 612.95652
B10: 900 | C10: 140.4692 | D10: 191.54891 | E10: 217.08877 | F10: 255.39855 | G10: 293.70833 | H10: 332.01811 | I10: 370.32789 | J10: 421.4076 | K10: 459.71739 | L10: 498.02717 | M10: 536.33695 | N10: 574.64673 | O10: 587.41666 | P10: 638.49637 | Q10: 689.57608 | R10: 715.11593
B11: 1050 | C11: 153.23913 | D11: 204.31884 | E11: 242.62862 | F11: 280.9384 | G11: 332.01811 | H11: 370.32789 | I11: 421.4076 | J11: 472.48731 | K11: 523.56702 | L11: 561.87681 | M11: 612.95652 | N11: 651.2663 | O11: 689.57608 | P11: 740.65579 | Q11: 778.96557 | R11: 830.04528
B12: 1200 | C12: 166.00906 | D12: 217.08877 | E12: 268.16848 | F12: 319.24819 | G12: 370.32789 | H12: 421.4076 | I12: 472.48731 | J12: 523.56702 | K12: 587.41666 | L12: 625.72644 | M12: 689.57608 | N12: 727.88586 | O12: 778.96557 | P12: 830.04528 | Q12: 881.12499 | R12: 932.2047
B13: 1350 | C13: 178.77898 | D13: 242.62862 | E13: 293.70833 | F13: 344.78804 | G13: 408.63768 | H13: 459.71739 | I13: 523.56702 | J13: 587.41666 | K13: 638.49637 | L13: 702.34601 | M13: 753.42572 | N13: 817.27535 | O13: 868.35506 | P13: 932.2047 | Q13: 983.28441 | R13: 1034.3641
B14: 1500 | C14: 191.54891 | D14: 255.39855 | E14: 319.24819 | F14: 357.55797 | G14: 446.94746 | H14: 510.7971 | I14: 574.64673 | J14: 638.49637 | K14: 702.34601 | L14: 766.19564 | M14: 830.04528 | N14: 893.89492 | O14: 957.74456 | P14: 1021.5942 | Q14: 1085.4438 | R14: 1149.2935
B15: 1650 | C15: 204.31884 | D15: 268.16848 | E15: 344.78804 | F15: 408.63768 | G15: 485.25724 | H15: 549.10688 | I15: 625.72644 | J15: 702.34601 | K15: 766.19564 | L15: 842.81521 | M15: 906.66485 | N15: 970.51448 | O15: 1047.134 | P15: 1110.9837 | Q15: 1187.6032 | R15: 1251.4529
B16: 1800 | C16: 217.08877 | D16: 293.70833 | E16: 370.32789 | F16: 446.94746 | G16: 523.56702 | H16: 600.18659 | I16: 676.80615 | J16: 753.42572 | K16: 830.04528 | L16: 906.66485 | M16: 983.28441 | N16: 1059.904 | O16: 1136.5235 | P16: 1213.1431 | Q16: 1276.9927 | R16: 1353.6123
B17: 1950 | C17: 229.85869 | D17: 306.47826 | E17: 395.86775 | F17: 472.48731 | G17: 574.64673 | H17: 638.49637 | I17: 715.11593 | J17: 817.27535 | K17: 893.89492 | L17: 970.51448 | M17: 1059.904 | N17: 1136.5235 | O17: 1225.913 | P17: 1302.5326 | Q17: 1379.1522 | R17: 1468.5417
B18: 2100 | C18: 242.62862 | D18: 332.01811 | E18: 421.4076 | F18: 510.7971 | G18: 600.18659 | H18: 676.80615 | I18: 766.19564 | J18: 881.12499 | K18: 957.74456 | L18: 1047.134 | M18: 1136.5235 | N18: 1225.913 | O18: 1302.5326 | P18: 1391.9221 | Q18: 1481.3116 | R18: 1570.7011
B19: 2250 | C19: 255.39855 | D19: 357.55797 | E19: 446.94746 | F19: 536.33695 | G19: 625.72644 | H19: 727.88586 | I19: 817.27535 | J19: 932.2047 | K19: 1021.5942 | L19: 1110.9837 | M19: 1213.1431 | N19: 1302.5326 | O19: 1391.9221 | P19: 1494.0815 | Q19: 1583.471 | R19: 1685.6304
... B21: 2550 | C21: 280.9384 | D21: 383.09782 | E21: 498.02717 | F21: 600.18659 | G21: 702.34601 | H21: 817.27535 | I21: 919.43477 | J21: 1034.3641 | K21: 1149.2935 | L21: 1251.4529 | M21: 1353.6123 | N21: 1468.5417 | O21: 1570.7011 | P21: 1685.6304 | Q21: 1787.7898 | R21: 1889.9493
C23: IntrudaGuard Doors
C24: 825 | D24: 875 | E24: 925 | F24: 975 | G24: 1025 | H24: 1075 | I24: 1125 | J24: 1175 | K24: 1225 | L24: 1275 | M24: 1325 | N24: 1375 | O24: 1425 | P24: 1500
B25: 2100 | C25: 866.46998 | D25: 879.32017 | E25: 892.17036 | F25: 905.02055 | G25: 930.72093 | H25: 956.42131 | I25: 982.12169 | J25: 1007.8221 | K25: 1059.2228 | L25: 1072.073 | M25: 1097.7734 | N25: 1123.4738 | O25: 1149.1742 | P25: 1239.1255
B26: 2200 | C26: 892.17036 | D26: 866.46998 | E26: 917.87074 | F26: 930.72093 | G26: 956.42131 | H26: 982.12169 | I26: 1007.8221 | J26: 1033.5224 | K26: 1084.9232 | L26: 1097.7734 | M26: 1123.4738 | N26: 1149.1742 | O26: 1174.8745 | P26: 1290.5263
B27: 2300 | C27: 917.87074 | D27: 892.17036 | E27: 930.72093 | F27: 956.42131 | G27: 982.12169 | H27: 1007.8221 | I27: 1033.5224 | J27: 1059.2228 | K27: 1059.2228 | L27: 1110.6236 | M27: 1149.1742 | N27: 1174.8745 | O27: 1200.5749 | P27: 1341.927
B28: 2400 | C28: 930.72093 | D28: 943.57112 | E28: 956.42131 | F28: 982.12169 | G28: 1007.8221 | H28: 1033.5224 | I28: 1059.2228 | J28: 1084.9232 | K28: 1110.6236 | L28: 1149.1742 | M28: 1174.8745 | N28: 1200.5749 | O28: 1226.2753 | P28: 1393.3278
B29: 2500 | C29: 956.42131 | D29: 969.2715 | E29: 982.12169 | F29: 1007.8221 | G29: 1033.5224 | H29: 1059.2228 | I29: 1084.9232 | J29: 1110.6236 | K29: 1162.0244 | L29: 1174.8745 | M29: 1200.5749 | N29: 1226.2753 | O29: 1251.9757 | P29: 1444.7285
B30: 2600 | C30: 982.12169 | D30: 1007.8221 | E30: 1033.5224 | F30: 1059.2228 | G30: 1084.9232 | H30: 1110.6236 | I30: 1136.324 | J30: 1187.7247 | K30: 1200.5749 | L30: 1226.2753 | M30: 1251.9757 | N30: 1277.6761 | O30: 1303.3764 | P30: 1496.1293
B32: Note: ALL price exclude GST

Sheet Retail Supply Extras
A1: Retail. - SUPPLY & INSTALL | B1: GOLDCO SECURITY GROUP PTY LTD 5572-2628
B2: PRODUCT LIST
B3: ALL PRICES ARE EXCULISVE OF GST
B4: Effective Date: 1/2/26
B6: ADDONS
B7: PET DOOR - SMALL (FITTED TO DOOR WHEN MAKE AT SAME TIME) | C7: 180 | D7: Each
B8: PET DOOR - MEDIUM (FITTED TO DOOR WHEN MAKE AT SAME TIME) | C8: 190 | D8: Each
B9: PET DOOR - LARGE (FITTED TO DOOR WHEN MAKE AT SAME TIME) | C9: 205 | D9: Each
B10: HOPPER HATCH (FITTED TO SCREEN WHEN MAKE AT SAME TIME) | C10: 35 | D10: Each
B11: HOPPER HATCH (PETWAYS FITTED TO SCREEN WHEN MAKE AT SAME TIME) | C11: 115 | D11: Each
B12: SNIB GUARDS (FITTED TO DOOR WHEN MAKE AT SAME TIME) | C12: 32 | D12: Each
B13: TRIPLE LOCKS (FITTED TO DOOR WHEN MAKE AT SAME TIME) | C13: 96 | D13: Each
B14: LOCK POSTS (WHEN FITTED TO CURRENT DOOR FRAMES) | C14: 75 | D14: Each
B15: TOP TRACKS (WHEN FITTED TO CURRENT DOOR FRAMES) | C15: 75 | D15: Each
B16: BOTTOM TRACK (WHEN FITTED TO CURRENT DOOR FRAMES) | C16: 75 | D16: Each
B17: BOX-OUTS | C17: PRICE ON REQUEST
B18: WATER CLOSERS | C18: PRICE ON REQUEST
B19: EXTRAS
B20: CALL OUT FEE | C20: 210
B21: PET DOOR TO EXISTING DOOR | C21: 340 | D21: Each
B22: ROLERS CHANGE | C22: 17.5 | D22: Each
B23: LOCK CHANGE (SINGLE) | C23: 102 | D23: Each
B24: LOCK CHANGE (TRIPLE) | C24: 230 | D24: Each
B25: REMESH FLYSCREEN WINDOW - STANDARD MESH (UNDER 1500 H) | C25: 55 | D25: Each
B26: REMESH FLYSCREEN WINDOW - STANDARD MESH (OVER 1500 H) | C26: 60 | D26: Each
B27: REMESH GRILLE WINDOW - STANDARD MESH (UNDER 1500 H) | C27: 85 | D27: Each
B28: REMESH GRILLE WINDOW - STANDARD MESH (OVER 1500 H) | C28: 91 | D28: Each
B29: REMESH DOORS - STANDARD MESH (UNDER 2400 IN HIGHT) | C29: 105 | D29: Each
B30: REMESH DOORS - STANDARD MESH (OVER 2400 IN HIGHT) | C30: 120 | D30: Each

Sheet 7mm Diamond
A1: Retail (Supply & Install)
F2: Pricing as at | G2: 46054 | K2: 0.06
C4: 7mm Diamond Windows
C5: 300 | D5: 450 | E5: 600 | F5: 750 | G5: 900 | H5: 1050 | I5: 1200 | J5: 1350 | K5: 1500
B6: 600 | C6: 95 | D6: 95 | E6: 95 | F6: 95 | G6: ='Data Sheet Grille'!G6*(1+$K$2) -> 121.51734 | H6: ='Data Sheet Grille'!H6*(1+$K$2) -> 141.77023 | I6: ='Data Sheet Grille'!I6*(1+$K$2) -> 162.02312 | J6: ='Data Sheet Grille'!J6*(1+$K$2) -> 182.27601 | K6: ='Data Sheet Grille'!K6*(1+$K$2) -> 202.52889
B7: 750 | C7: 95 | D7: 95 | E7: 95 | F7: ='Data Sheet Grille'!F7*(1+$K$2) -> 126.58056 | G7: ='Data Sheet Grille'!G7*(1+$K$2) -> 151.89667 | H7: ='Data Sheet Grille'!H7*(1+$K$2) -> 177.21278 | I7: ='Data Sheet Grille'!I7*(1+$K$2) -> 202.52889 | J7: ='Data Sheet Grille'!J7*(1+$K$2) -> 227.84501 | K7: ='Data Sheet Grille'!K7*(1+$K$2) -> 253.16112
B8: 900 | C8: 95 | D8: 95 | E8: ='Data Sheet Grille'!E8*(1+$K$2) -> 121.51734 | F8: ='Data Sheet Grille'!F8*(1+$K$2) -> 151.89667 | G8: ='Data Sheet Grille'!G8*(1+$K$2) -> 182.27601 | H8: ='Data Sheet Grille'!H8*(1+$K$2) -> 212.65534 | I8: ='Data Sheet Grille'!I8*(1+$K$2) -> 243.03467 | J8: ='Data Sheet Grille'!J8*(1+$K$2) -> 273.41401 | K8: ='Data Sheet Grille'!K8*(1+$K$2) -> 303.79334
B9: 1050 | C9: 95 | D9: ='Data Sheet Grille'!D9*(1+$K$2) -> 106.32767 | E9: ='Data Sheet Grille'!E9*(1+$K$2) -> 141.77023 | F9: ='Data Sheet Grille'!F9*(1+$K$2) -> 177.21278 | G9: ='Data Sheet Grille'!G9*(1+$K$2) -> 212.65534 | H9: ='Data Sheet Grille'!H9*(1+$K$2) -> 248.0979 | I9: ='Data Sheet Grille'!I9*(1+$K$2) -> 283.54045 | J9: ='Data Sheet Grille'!J9*(1+$K$2) -> 318.98301 | K9: ='Data Sheet Grille'!K9*(1+$K$2) -> 354.42557
B10: 1200 | C10: 95 | D10: ='Data Sheet Grille'!D10*(1+$K$2) -> 121.51734 | E10: ='Data Sheet Grille'!E10*(1+$K$2) -> 162.02312 | F10: ='Data Sheet Grille'!F10*(1+$K$2) -> 202.52889 | G10: ='Data Sheet Grille'!G10*(1+$K$2) -> 243.03467 | H10: ='Data Sheet Grille'!H10*(1+$K$2) -> 283.54045 | I10: ='Data Sheet Grille'!I10*(1+$K$2) -> 324.04623 | J10: ='Data Sheet Grille'!J10*(1+$K$2) -> 364.55201 | K10: ='Data Sheet Grille'!K10*(1+$K$2) -> 405.05779
B11: 1350 | C11: 95 | D11: ='Data Sheet Grille'!D11*(1+$K$2) -> 136.707 | E11: ='Data Sheet Grille'!E11*(1+$K$2) -> 182.27601 | F11: ='Data Sheet Grille'!F11*(1+$K$2) -> 227.84501 | G11: ='Data Sheet Grille'!G11*(1+$K$2) -> 273.41401 | H11: ='Data Sheet Grille'!H11*(1+$K$2) -> 318.98301 | I11: ='Data Sheet Grille'!I11*(1+$K$2) -> 364.55201 | J11: ='Data Sheet Grille'!J11*(1+$K$2) -> 410.12101 | K11: ='Data Sheet Grille'!K11*(1+$K$2) -> 455.69001
B12: 1500 | C12: 95 | D12: ='Data Sheet Grille'!D12*(1+$K$2) -> 151.89667 | E12: ='Data Sheet Grille'!E12*(1+$K$2) -> 202.52889 | F12: ='Data Sheet Grille'!F12*(1+$K$2) -> 253.16112 | G12: ='Data Sheet Grille'!G12*(1+$K$2) -> 303.79334 | H12: ='Data Sheet Grille'!H12*(1+$K$2) -> 354.42557 | I12: ='Data Sheet Grille'!I12*(1+$K$2) -> 405.05779 | J12: ='Data Sheet Grille'!J12*(1+$K$2) -> 455.69001 | K12: ='Data Sheet Grille'!K12*(1+$K$2) -> 506.32224
B13: 1650 | C13: 95 | D13: ='Data Sheet Grille'!D13*(1+$K$2) -> 167.08634 | E13: ='Data Sheet Grille'!E13*(1+$K$2) -> 222.78178 | F13: ='Data Sheet Grille'!F13*(1+$K$2) -> 278.47723 | G13: ='Data Sheet Grille'!G13*(1+$K$2) -> 334.17268 | H13: ='Data Sheet Grille'!H13*(1+$K$2) -> 389.86812 | I13: ='Data Sheet Grille'!I13*(1+$K$2) -> 445.56357 | J13: ='Data Sheet Grille'!J13*(1+$K$2) -> 501.25901 | K13: ='Data Sheet Grille'!K13*(1+$K$2) -> 556.95446
B14: 1800 | C14: ='Data Sheet Grille'!C14*(1+$K$2) -> 121.51734 | D14: ='Data Sheet Grille'!D14*(1+$K$2) -> 182.27601 | E14: ='Data Sheet Grille'!E14*(1+$K$2) -> 243.03467 | F14: ='Data Sheet Grille'!F14*(1+$K$2) -> 303.79334 | G14: ='Data Sheet Grille'!G14*(1+$K$2) -> 364.55201 | H14: ='Data Sheet Grille'!H14*(1+$K$2) -> 425.31068 | I14: ='Data Sheet Grille'!I14*(1+$K$2) -> 486.06935 | J14: ='Data Sheet Grille'!J14*(1+$K$2) -> 546.82802 | K14: ='Data Sheet Grille'!K14*(1+$K$2) -> 607.58668
B15: 1950 | C15: ='Data Sheet Grille'!C15*(1+$K$2) -> 131.64378 | D15: ='Data Sheet Grille'!D15*(1+$K$2) -> 197.46567 | E15: ='Data Sheet Grille'!E15*(1+$K$2) -> 263.28756 | F15: ='Data Sheet Grille'!F15*(1+$K$2) -> 329.10945 | G15: ='Data Sheet Grille'!G15*(1+$K$2) -> 394.93134 | H15: ='Data Sheet Grille'!H15*(1+$K$2) -> 460.75324 | I15: ='Data Sheet Grille'!I15*(1+$K$2) -> 526.57513 | J15: ='Data Sheet Grille'!J15*(1+$K$2) -> 592.39702 | K15: ='Data Sheet Grille'!K15*(1+$K$2) -> 658.21891
B16: 2100 | C16: ='Data Sheet Grille'!C16*(1+$K$2) -> 141.77023 | D16: ='Data Sheet Grille'!D16*(1+$K$2) -> 212.65534 | E16: ='Data Sheet Grille'!E16*(1+$K$2) -> 283.54045 | F16: ='Data Sheet Grille'!F16*(1+$K$2) -> 354.42557 | G16: ='Data Sheet Grille'!G16*(1+$K$2) -> 425.31068 | H16: ='Data Sheet Grille'!H16*(1+$K$2) -> 496.19579 | I16: ='Data Sheet Grille'!I16*(1+$K$2) -> 567.08091 | J16: ='Data Sheet Grille'!J16*(1+$K$2) -> 637.96602 | K16: ='Data Sheet Grille'!K16*(1+$K$2) -> 708.85113
B17: 2250 | C17: ='Data Sheet Grille'!C17*(1+$K$2) -> 151.89667 | D17: ='Data Sheet Grille'!D17*(1+$K$2) -> 227.84501 | E17: ='Data Sheet Grille'!E17*(1+$K$2) -> 303.79334 | F17: ='Data Sheet Grille'!F17*(1+$K$2) -> 379.74168 | G17: ='Data Sheet Grille'!G17*(1+$K$2) -> 455.69001 | H17: ='Data Sheet Grille'!H17*(1+$K$2) -> 531.63835 | I17: ='Data Sheet Grille'!I17*(1+$K$2) -> 607.58668 | J17: ='Data Sheet Grille'!J17*(1+$K$2) -> 683.53502 | K17: ='Data Sheet Grille'!K17*(1+$K$2) -> 759.48336
B18: 2400 | C18: ='Data Sheet Grille'!C18*(1+$K$2) -> 162.02312 | D18: ='Data Sheet Grille'!D18*(1+$K$2) -> 243.03467 | E18: ='Data Sheet Grille'!E18*(1+$K$2) -> 324.04623 | F18: ='Data Sheet Grille'!F18*(1+$K$2) -> 405.05779 | G18: ='Data Sheet Grille'!G18*(1+$K$2) -> 486.06935 | H18: ='Data Sheet Grille'!H18*(1+$K$2) -> 567.08091 | I18: ='Data Sheet Grille'!I18*(1+$K$2) -> 648.09246 | J18: ='Data Sheet Grille'!J18*(1+$K$2) -> 729.10402 | K18: ='Data Sheet Grille'!K18*(1+$K$2) -> 810.11558
B19: 2550 | C19: ='Data Sheet Grille'!C19*(1+$K$2) -> 172.14956 | D19: ='Data Sheet Grille'!D19*(1+$K$2) -> 258.22434 | E19: ='Data Sheet Grille'!E19*(1+$K$2) -> 344.29912 | F19: ='Data Sheet Grille'!F19*(1+$K$2) -> 430.3739 | G19: ='Data Sheet Grille'!G19*(1+$K$2) -> 516.44868 | H19: ='Data Sheet Grille'!H19*(1+$K$2) -> 602.52346 | I19: ='Data Sheet Grille'!I19*(1+$K$2) -> 688.59824 | J19: ='Data Sheet Grille'!J19*(1+$K$2) -> 774.67302 | K19: ='Data Sheet Grille'!K19*(1+$K$2) -> 860.7478
C21: WINDOWS EXTRAS | F21: UNDER 1500 HIGH ADD | I21: OVER 1500 HIGH ADD
C22: PETMESH | F22: 69 | I22: 94
C23: MIDGEE MESH | F23: 22 | I23: 32
C24: ALUMINIUM MESH | F24: 45 | I24: 66
C25: STAINLESS STEEL MESH | F25: 74 | I25: 98
K28: 0.06
C29: 7mm Diamond Doors
C30: 800 | D30: 900 | E30: 1000 | F30: 1100 | G30: 1200 | H30: 1300 | I30: 1400 | J30: 1500 | K30: 1600
B31: 2100 | C31: ='Data Sheet Grille'!C30*(1+$K$28) -> 609.64131 | D31: ='Data Sheet Grille'!D30*(1+$K$28) -> 625.6845 | E31: ='Data Sheet Grille'!E30*(1+$K$28) -> 641.7277 | F31: ='Data Sheet Grille'!F30*(1+$K$28) -> 657.77089 | G31: ='Data Sheet Grille'!G30*(1+$K$28) -> 673.81408 | H31: ='Data Sheet Grille'!H30*(1+$K$28) -> 689.85727 | I31: ='Data Sheet Grille'!I30*(1+$K$28) -> 705.90047 | J31: ='Data Sheet Grille'!J30*(1+$K$28) -> 721.94366 | K31: ='Data Sheet Grille'!K30*(1+$K$28) -> 737.98685
B32: 2200 | C32: ='Data Sheet Grille'!C31*(1+$K$28) -> 625.6845 | D32: ='Data Sheet Grille'!D31*(1+$K$28) -> 641.7277 | E32: ='Data Sheet Grille'!E31*(1+$K$28) -> 657.77089 | F32: ='Data Sheet Grille'!F31*(1+$K$28) -> 673.81408 | G32: ='Data Sheet Grille'!G31*(1+$K$28) -> 689.85727 | H32: ='Data Sheet Grille'!H31*(1+$K$28) -> 705.90047 | I32: ='Data Sheet Grille'!I31*(1+$K$28) -> 721.94366 | J32: ='Data Sheet Grille'!J31*(1+$K$28) -> 737.98685 | K32: ='Data Sheet Grille'!K31*(1+$K$28) -> 754.03004
B33: 2300 | C33: ='Data Sheet Grille'!C32*(1+$K$28) -> 641.7277 | D33: ='Data Sheet Grille'!D32*(1+$K$28) -> 657.77089 | E33: ='Data Sheet Grille'!E32*(1+$K$28) -> 673.81408 | F33: ='Data Sheet Grille'!F32*(1+$K$28) -> 689.85727 | G33: ='Data Sheet Grille'!G32*(1+$K$28) -> 705.90047 | H33: ='Data Sheet Grille'!H32*(1+$K$28) -> 721.94366 | I33: ='Data Sheet Grille'!I32*(1+$K$28) -> 737.98685 | J33: ='Data Sheet Grille'!J32*(1+$K$28) -> 754.03004 | K33: ='Data Sheet Grille'!K32*(1+$K$28) -> 770.07324
B34: 2400 | C34: ='Data Sheet Grille'!C33*(1+$K$28) -> 657.77089 | D34: ='Data Sheet Grille'!D33*(1+$K$28) -> 673.81408 | E34: ='Data Sheet Grille'!E33*(1+$K$28) -> 689.85727 | F34: ='Data Sheet Grille'!F33*(1+$K$28) -> 705.90047 | G34: ='Data Sheet Grille'!G33*(1+$K$28) -> 721.94366 | H34: ='Data Sheet Grille'!H33*(1+$K$28) -> 737.98685 | I34: ='Data Sheet Grille'!I33*(1+$K$28) -> 754.03004 | J34: ='Data Sheet Grille'!J33*(1+$K$28) -> 770.07324 | K34: ='Data Sheet Grille'!K33*(1+$K$28) -> 786.11643
B35: 2500 | C35: ='Data Sheet Grille'!C34*(1+$K$28) -> 673.81408 | D35: ='Data Sheet Grille'!D34*(1+$K$28) -> 689.85727 | E35: ='Data Sheet Grille'!E34*(1+$K$28) -> 705.90047 | F35: ='Data Sheet Grille'!F34*(1+$K$28) -> 721.94366 | G35: ='Data Sheet Grille'!G34*(1+$K$28) -> 737.98685 | H35: ='Data Sheet Grille'!H34*(1+$K$28) -> 754.03004 | I35: ='Data Sheet Grille'!I34*(1+$K$28) -> 770.07324 | J35: ='Data Sheet Grille'!J34*(1+$K$28) -> 786.11643 | K35: ='Data Sheet Grille'!K34*(1+$K$28) -> 802.15962
B36: 2600 | C36: ='Data Sheet Grille'!C35*(1+$K$28) -> 689.85727 | D36: ='Data Sheet Grille'!D35*(1+$K$28) -> 705.90047 | E36: ='Data Sheet Grille'!E35*(1+$K$28) -> 721.94366 | F36: ='Data Sheet Grille'!F35*(1+$K$28) -> 737.98685 | G36: ='Data Sheet Grille'!G35*(1+$K$28) -> 754.03004 | H36: ='Data Sheet Grille'!H35*(1+$K$28) -> 770.07324 | I36: ='Data Sheet Grille'!I35*(1+$K$28) -> 786.11643 | J36: ='Data Sheet Grille'!J35*(1+$K$28) -> 802.15962 | K36: ='Data Sheet Grille'!K35*(1+$K$28) -> 818.20281
C38: DOOR EXTRAS | F38: UNDER 2400 HIGH ADD | I38: OVER 2400 HIGH ADD
C39: PETMESH | F39: 110 | I39: 134
C40: MIDGEE MESH | F40: 46 | I40: 55
C41: ALUMINIUM MESH | F41: 90 | I41: 110
C42: STAINLESS STEEL MESH | F42: 145 | I42: 176
B44: Note: ALL price exclude GST

Sheet Data Sheet Grille
A1: Retail (Supply & Install)
A2: DO NOT USE FOR PRICING
C4: 7mm Diamond Windows
C5: 300 | D5: 450 | E5: 600 | F5: 750 | G5: 900 | H5: 1050 | I5: 1200 | J5: 1350 | K5: 1500
B6: 600 | C6: 90 | D6: 90 | E6: 90 | F6: 90 | G6: 107.13925 | H6: 124.99579 | I6: 142.85233 | J6: 160.70887 | K6: 178.56542
B7: 750 | C7: 90 | D7: 90 | E7: 90 | F7: 111.60339 | G7: 133.92406 | H7: 156.24474 | I7: 178.56542 | J7: 200.88609 | K7: 223.20677
B8: 900 | C8: 90 | D8: 90 | E8: 107.13925 | F8: 133.92406 | G8: 160.70887 | H8: 187.49369 | I8: 214.2785 | J8: 241.06331 | K8: 267.84812 | M8: `
B9: 1050 | C9: 90 | D9: 93.746843 | E9: 124.99579 | F9: 156.24474 | G9: 187.49369 | H9: 218.74263 | I9: 249.99158 | J9: 281.24053 | K9: 312.48948
B10: 1200 | C10: 90 | D10: 107.13925 | E10: 142.85233 | F10: 178.56542 | G10: 214.2785 | H10: 249.99158 | I10: 285.70467 | J10: 321.41775 | K10: 357.13083
B11: 1350 | C11: 90 | D11: 120.53166 | E11: 160.70887 | F11: 200.88609 | G11: 241.06331 | H11: 281.24053 | I11: 321.41775 | J11: 361.59497 | K11: 401.77219
B12: 1500 | C12: 90 | D12: 133.92406 | E12: 178.56542 | F12: 223.20677 | G12: 267.84812 | H12: 312.48948 | I12: 357.13083 | J12: 401.77219 | K12: 446.41354
B13: 1650 | C13: 90 | D13: 147.31647 | E13: 196.42196 | F13: 245.52745 | G13: 294.63294 | H13: 343.73843 | I13: 392.84392 | J13: 441.9494 | K13: 491.05489
B14: 1800 | C14: 107.13925 | D14: 160.70887 | E14: 214.2785 | F14: 267.84812 | G14: 321.41775 | H14: 374.98737 | I14: 428.557 | J14: 482.12662 | K14: 535.69625
B15: 1950 | C15: 116.06752 | D15: 174.10128 | E15: 232.13504 | F15: 290.1688 | G15: 348.20256 | H15: 406.23632 | I15: 464.27008 | J15: 522.30384 | K15: 580.3376
B16: 2100 | C16: 124.99579 | D16: 187.49369 | E16: 249.99158 | F16: 312.48948 | G16: 374.98737 | H16: 437.48527 | I16: 499.98316 | J16: 562.48106 | K16: 624.97896
B17: 2250 | C17: 133.92406 | D17: 200.88609 | E17: 267.84812 | F17: 334.81016 | G17: 401.77219 | H17: 468.73422 | I17: 535.69625 | J17: 602.65828 | K17: 669.62031
B18: 2400 | C18: 142.85233 | D18: 214.2785 | E18: 285.70467 | F18: 357.13083 | G18: 428.557 | H18: 499.98316 | I18: 571.40933 | J18: 642.8355 | K18: 714.26166
B19: 2550 | C19: 151.7806 | D19: 227.67091 | E19: 303.56121 | F19: 379.45151 | G19: 455.34181 | H19: 531.23211 | I19: 607.12241 | J19: 683.01272 | K19: 758.90302
C21: WINDOWS EXTRAS - MAX 1200 | F21: UNDER 1500 HIGH ADD | I21: OVER 1500 HIGH ADD
C22: PETMESH | F22: 65 | I22: 88
C23: MIDGEE MESH | F23: 20 | I23: 30
C24: ALUMINIUM MESH | F24: 43 | I24: 62
C25: STAINLESS STEEL MESH | F25: 69 | I25: 92
C28: 7mm Diamond Doors
C29: 800 | D29: 900 | E29: 1000 | F29: 1100 | G29: 1200 | H29: 1300 | I29: 1400 | J29: 1500 | K29: 1600
B30: 2100 | C30: 537.50777 | D30: 551.65271 | E30: 565.79765 | F30: 579.94259 | G30: 594.08753 | H30: 608.23248 | I30: 622.37742 | J30: 636.52236 | K30: 650.6673
B31: 2200 | C31: 551.65271 | D31: 565.79765 | E31: 579.94259 | F31: 594.08753 | G31: 608.23248 | H31: 622.37742 | I31: 636.52236 | J31: 650.6673 | K31: 664.81224
B32: 2300 | C32: 565.79765 | D32: 579.94259 | E32: 594.08753 | F32: 608.23248 | G32: 622.37742 | H32: 636.52236 | I32: 650.6673 | J32: 664.81224 | K32: 678.95718
B33: 2400 | C33: 579.94259 | D33: 594.08753 | E33: 608.23248 | F33: 622.37742 | G33: 636.52236 | H33: 650.6673 | I33: 664.81224 | J33: 678.95718 | K33: 693.10212
B34: 2500 | C34: 594.08753 | D34: 608.23248 | E34: 622.37742 | F34: 636.52236 | G34: 650.6673 | H34: 664.81224 | I34: 678.95718 | J34: 693.10212 | K34: 707.24707
B35: 2600 | C35: 608.23248 | D35: 622.37742 | E35: 636.52236 | F35: 650.6673 | G35: 664.81224 | H35: 678.95718 | I35: 693.10212 | J35: 707.24707 | K35: 721.39201
C37: DOOR EXTRAS - MAX 1200 | F37: UNDER 2400 HIGH ADD | I37: OVER 2400 HIGH ADD
C38: PETMESH | F38: 102 | I38: 125
C39: MIDGEE MESH | F39: 43 | I39: 51
C40: ALUMINIUM MESH | F40: 84 | I40: 102
C41: STAINLESS STEEL MESH | F41: 135 | I41: 165
B43: STANDARD COLOURS
B44: CLEAR ANODISED | D44: PRIMROSE GLOSS | F44: DEEP OCEAN MATT | H44: BRONZE ANODISED | J44: STONE BEIGE MATT
B45: ULTRA SILVER GLOSS | D45: PEARL WHITE GLOSS | F45: PEARL WHITE GLOSS | H45: WOODLAND GREY MATT | J45: BROWN SATIN
B46: BLACK | D46: ANODIC MATT NATURAL
...

Sheet Fly Screens
A1: Retail (Supply & Install)
F2: Pricing as at | G2: 46159 | K2: 0.065
C4: Flyscreens - Standard Mesh
C5: 1200 | D5: 1500 | E5: 1800 | F5: 2100 | G5: 2400 | H5: 2700 | I5: 3000
B6: 1500 | C6: ='DATA_Fly Screens'!C6*(1+'Fly Screens'!$K$2) -> 89.561281 | D6: ='DATA_Fly Screens'!D6*(1+'Fly Screens'!$K$2) -> 111.9516 | E6: ='DATA_Fly Screens'!E6*(1+'Fly Screens'!$K$2) -> 134.34192 | F6: ='DATA_Fly Screens'!F6*(1+'Fly Screens'!$K$2) -> 156.73224 | G6: ='DATA_Fly Screens'!G6*(1+'Fly Screens'!$K$2) -> 179.12256 | H6: ='DATA_Fly Screens'!H6*(1+'Fly Screens'!$K$2) -> 201.51288 | I6: ='DATA_Fly Screens'!I6*(1+'Fly Screens'!$K$2) -> 223.9032
B7: 1800 | C7: ='DATA_Fly Screens'!C7*(1+'Fly Screens'!$K$2) -> 107.47354 | D7: ='DATA_Fly Screens'!D7*(1+'Fly Screens'!$K$2) -> 134.34192 | E7: ='DATA_Fly Screens'!E7*(1+'Fly Screens'!$K$2) -> 161.21031 | F7: ='DATA_Fly Screens'!F7*(1+'Fly Screens'!$K$2) -> 188.07869 | G7: ='DATA_Fly Screens'!G7*(1+'Fly Screens'!$K$2) -> 214.94708 | H7: ='DATA_Fly Screens'!H7*(1+'Fly Screens'!$K$2) -> 241.81546 | I7: ='DATA_Fly Screens'!I7*(1+'Fly Screens'!$K$2) -> 268.68384
B8: 2100 | C8: ='DATA_Fly Screens'!C8*(1+'Fly Screens'!$K$2) -> 125.38579 | D8: ='DATA_Fly Screens'!D8*(1+'Fly Screens'!$K$2) -> 156.73224 | E8: ='DATA_Fly Screens'!E8*(1+'Fly Screens'!$K$2) -> 188.07869 | F8: ='DATA_Fly Screens'!F8*(1+'Fly Screens'!$K$2) -> 219.42514 | G8: ='DATA_Fly Screens'!G8*(1+'Fly Screens'!$K$2) -> 250.77159 | H8: ='DATA_Fly Screens'!H8*(1+'Fly Screens'!$K$2) -> 282.11804 | I8: ='DATA_Fly Screens'!I8*(1+'Fly Screens'!$K$2) -> 313.46449
B9: 2400 | C9: ='DATA_Fly Screens'!C9*(1+'Fly Screens'!$K$2) -> 143.29805 | D9: ='DATA_Fly Screens'!D9*(1+'Fly Screens'!$K$2) -> 179.12256 | E9: ='DATA_Fly Screens'!E9*(1+'Fly Screens'!$K$2) -> 214.94708 | F9: ='DATA_Fly Screens'!F9*(1+'Fly Screens'!$K$2) -> 250.77159 | G9: ='DATA_Fly Screens'!G9*(1+'Fly Screens'!$K$2) -> 286.5961 | H9: ='DATA_Fly Screens'!H9*(1+'Fly Screens'!$K$2) -> 322.42061 | I9: ='DATA_Fly Screens'!I9*(1+'Fly Screens'!$K$2) -> 358.24513
B10: 2700 | C10: ='DATA_Fly Screens'!C10*(1+'Fly Screens'!$K$2) -> 161.21031 | D10: ='DATA_Fly Screens'!D10*(1+'Fly Screens'!$K$2) -> 201.51288 | E10: ='DATA_Fly Screens'!E10*(1+'Fly Screens'!$K$2) -> 241.81546 | F10: ='DATA_Fly Screens'!F10*(1+'Fly Screens'!$K$2) -> 282.11804 | G10: ='DATA_Fly Screens'!G10*(1+'Fly Screens'!$K$2) -> 322.42061 | H10: ='DATA_Fly Screens'!H10*(1+'Fly Screens'!$K$2) -> 362.72319 | I10: ='DATA_Fly Screens'!I10*(1+'Fly Screens'!$K$2) -> 403.02577
B11: 3000 | C11: ='DATA_Fly Screens'!C11*(1+'Fly Screens'!$K$2) -> 179.12256 | D11: ='DATA_Fly Screens'!D11*(1+'Fly Screens'!$K$2) -> 223.9032 | E11: ='DATA_Fly Screens'!E11*(1+'Fly Screens'!$K$2) -> 268.68384 | F11: ='DATA_Fly Screens'!F11*(1+'Fly Screens'!$K$2) -> 313.46449 | G11: ='DATA_Fly Screens'!G11*(1+'Fly Screens'!$K$2) -> 358.24513 | H11: ='DATA_Fly Screens'!H11*(1+'Fly Screens'!$K$2) -> 403.02577 | I11: ='DATA_Fly Screens'!I11*(1+'Fly Screens'!$K$2) -> 447.80641
B13: Additional charge of $15+gst for double hung windows
C15: WINDOWS EXTRAS | F15: UNDER 1500 HIGH ADD | I15: OVER 1500 HIGH ADD
C16: PETMESH | F16: 75 | I16: 101
C17: MIDGEE MESH | F17: 25 | I17: 35
C18: ALUMINIUM MESH | F18: 50 | I18: 71
C19: STAINLESS STEEL MESH | F19: 80 | I19: 105
K21: 0.065
C22: Flyscreen Sliding Doors - Standard Mesh
C23: 800 | D23: 900 | E23: 1000 | F23: 1100 | G23: 1200 | H23: 1300 | I23: 1400 | J23: 1500 | K23: 1600
B24: 2100 | C24: =('DATA_Fly Screens'!C21)*(1+$K$21) -> 415.56886 | D24: =('DATA_Fly Screens'!D21)*(1+$K$21) -> 431.55228 | E24: =('DATA_Fly Screens'!E21)*(1+$K$21) -> 447.53569 | F24: =('DATA_Fly Screens'!F21)*(1+$K$21) -> 463.51911 | G24: =('DATA_Fly Screens'!G21)*(1+$K$21) -> 479.50253 | H24: =('DATA_Fly Screens'!H21)*(1+$K$21) -> 495.48595 | I24: =('DATA_Fly Screens'!I21)*(1+$K$21) -> 511.46936 | J24: =('DATA_Fly Screens'!J21)*(1+$K$21) -> 527.45278 | K24: =('DATA_Fly Screens'!K21)*(1+$K$21) -> 543.4362
B25: 2200 | C25: =('DATA_Fly Screens'!C22)*(1+$K$21) -> 431.55228 | D25: =('DATA_Fly Screens'!D22)*(1+$K$21) -> 447.53569 | E25: =('DATA_Fly Screens'!E22)*(1+$K$21) -> 463.51911 | F25: =('DATA_Fly Screens'!F22)*(1+$K$21) -> 479.50253 | G25: =('DATA_Fly Screens'!G22)*(1+$K$21) -> 495.48595 | H25: =('DATA_Fly Screens'!H22)*(1+$K$21) -> 511.46936 | I25: =('DATA_Fly Screens'!I22)*(1+$K$21) -> 527.45278 | J25: =('DATA_Fly Screens'!J22)*(1+$K$21) -> 543.4362 | K25: =('DATA_Fly Screens'!K22)*(1+$K$21) -> 559.41962
B26: 2300 | C26: =('DATA_Fly Screens'!C23)*(1+$K$21) -> 447.53569 | D26: =('DATA_Fly Screens'!D23)*(1+$K$21) -> 463.51911 | E26: =('DATA_Fly Screens'!E23)*(1+$K$21) -> 479.50253 | F26: =('DATA_Fly Screens'!F23)*(1+$K$21) -> 495.48595 | G26: =('DATA_Fly Screens'!G23)*(1+$K$21) -> 511.46936 | H26: =('DATA_Fly Screens'!H23)*(1+$K$21) -> 527.45278 | I26: =('DATA_Fly Screens'!I23)*(1+$K$21) -> 543.4362 | J26: =('DATA_Fly Screens'!J23)*(1+$K$21) -> 559.41962 | K26: =('DATA_Fly Screens'!K23)*(1+$K$21) -> 575.40303
B27: 2400 | C27: =('DATA_Fly Screens'!C24)*(1+$K$21) -> 463.51911 | D27: =('DATA_Fly Screens'!D24)*(1+$K$21) -> 479.50253 | E27: =('DATA_Fly Screens'!E24)*(1+$K$21) -> 495.48595 | F27: =('DATA_Fly Screens'!F24)*(1+$K$21) -> 511.46936 | G27: =('DATA_Fly Screens'!G24)*(1+$K$21) -> 527.45278 | H27: =('DATA_Fly Screens'!H24)*(1+$K$21) -> 543.4362 | I27: =('DATA_Fly Screens'!I24)*(1+$K$21) -> 559.41962 | J27: =('DATA_Fly Screens'!J24)*(1+$K$21) -> 575.40303 | K27: =('DATA_Fly Screens'!K24)*(1+$K$21) -> 591.38645
B28: 2500 | C28: =('DATA_Fly Screens'!C25)*(1+$K$21) -> 479.50253 | D28: =('DATA_Fly Screens'!D25)*(1+$K$21) -> 495.48595 | E28: =('DATA_Fly Screens'!E25)*(1+$K$21) -> 511.46936 | F28: =('DATA_Fly Screens'!F25)*(1+$K$21) -> 527.45278 | G28: =('DATA_Fly Screens'!G25)*(1+$K$21) -> 543.4362 | H28: =('DATA_Fly Screens'!H25)*(1+$K$21) -> 559.41962 | I28: =('DATA_Fly Screens'!I25)*(1+$K$21) -> 575.40303 | J28: =('DATA_Fly Screens'!J25)*(1+$K$21) -> 591.38645 | K28: =('DATA_Fly Screens'!K25)*(1+$K$21) -> 607.36987
B29: 2600 | C29: =('DATA_Fly Screens'!C26)*(1+$K$21) -> 495.48595 | D29: =('DATA_Fly Screens'!D26)*(1+$K$21) -> 511.46936 | E29: =('DATA_Fly Screens'!E26)*(1+$K$21) -> 527.45278 | F29: =('DATA_Fly Screens'!F26)*(1+$K$21) -> 543.4362 | G29: =('DATA_Fly Screens'!G26)*(1+$K$21) -> 559.41962 | H29: =('DATA_Fly Screens'!H26)*(1+$K$21) -> 575.40303 | I29: =('DATA_Fly Screens'!I26)*(1+$K$21) -> 591.38645 | J29: =('DATA_Fly Screens'!J26)*(1+$K$21) -> 607.36987 | K29: =('DATA_Fly Screens'!K26)*(1+$K$21) -> 623.35329
K31: 0.065
C32: Flyscreen Hinged Doors - Standard Mesh
C33: 800 | D33: 900 | E33: 1000 | F33: 1100 | G33: 1200 | H33: 1300 | I33: 1400 | J33: 1500 | K33: 1600
